Workbook

Sheet Revenue model
A1: month | C1: 1 | D1: =1+C1 -> 2 | E1: =1+D1 -> 3 | F1: =1+E1 -> 4 | G1: =1+F1 -> 5 | H1: =1+G1 -> 6 | I1: =1+H1 -> 7 | J1: =1+I1 -> 8 | K1: =1+J1 -> 9 | ... AL1: =1+AK1 -> 36
A2: New Customers | C2: 0 | D2: 1 | E2: 2 | F2: 2 | G2: 4 | H2: 4 | I2: 5 | J2: 5 | K2: 6 | L2: 6 | M2: 8 | N2: 8 | O2: 8 | P2: 8 | Q2: 10 | R2: 10 | S2: 10 | T2: 10 | U2: 10 | V2: 10 | W2: 10 | X2: 10 | Y2: 10 | Z2: 10 | AA2: 12 | AB2: 12 | AC2: 12 | AD2: 12 | AE2: 15 | AF2: 15 | AG2: 15 | AH2: 15 | AI2: 20 | AJ2: 20 | AK2: 20 | AL2: 20
A3: New Bookings | C3: =C2*$B14 -> 0 | D3: =D2*$B14 -> 30000 | E3: =E2*$B14 -> 60000 | F3: =F2*$B14 -> 60000 | G3: =G2*$B14 -> 120000 | H3: =H2*$B14 -> 120000 | I3: =I2*$B14 -> 150000 | J3: =J2*$B14 -> 150000 | ... AL3: =AL2*$B14 -> 600000
A5: New MRR | C5: =SUM(C12:C47) -> 0 | D5: =SUM(D12:D47) -> 2500 | E5: =SUM(E12:E47) -> 7500 | F5: =SUM(F12:F47) -> 12500 | G5: =SUM(G12:G47) -> 22500 | H5: =SUM(H12:H47) -> 32500 | I5: =SUM(I12:I47) -> 45000 | J5: =SUM(J12:J47) -> 57500 | ... AL5: =SUM(AL12:AL47) -> 470000
A7: Renewals | C7: 0 | D7: 0 | E7: 0 | F7: 0 | G7: 0 | H7: 0 | I7: 0 | J7: 0 | K7: 0 | L7: 0 | M7: 0 | N7: 0 | O7: =SUM(O49:O73) -> 0 | P7: =SUM(P49:P73) -> 2000 | Q7: =SUM(Q49:Q73) -> 6000 | R7: =SUM(R49:R73) -> 10000 | S7: =SUM(S49:S73) -> 18000 | T7: =SUM(T49:T73) -> 26000 | U7: =SUM(U49:U73) -> 36000 | V7: =SUM(V49:V73) -> 46000 | ... AL7: =SUM(AL49:AL73) -> 352800
A8: Professional Services | C8: =C3*$B$16 -> 0 | D8: =D3*$B$16 -> 9000 | E8: =E3*$B$16 -> 18000 | F8: =F3*$B$16 -> 18000 | G8: =G3*$B$16 -> 36000 | H8: =H3*$B$16 -> 36000 | I8: =I3*$B$16 -> 45000 | J8: =J3*$B$16 -> 45000 | ... AL8: =AL3*$B$16 -> 180000
A9: Total Monthly Revenue | C9: =C5+C7 -> 0 | D9: =D5+D7+D8 -> 11500 | E9: =E5+E7+E8 -> 25500 | F9: =F5+F7+F8 -> 30500 | G9: =G5+G7+G8 -> 58500 | H9: =H5+H7+H8 -> 68500 | I9: =I5+I7+I8 -> 90000 | J9: =J5+J7+J8 -> 102500 | K9: =K5+K7+K8 -> 126500 | ... AL9: =AL5+AL7+AL8 -> 1002800
A10: Total Quarterly Revenue | E10: =SUM(C9:E9) -> 37000 | H10: =SUM(F9:H9) -> 157500 | K10: =SUM(I9:K9) -> 319000 | N10: =SUM(L9:N9) -> 520500 | Q10: =SUM(O9:Q9) -> 739500 | T10: =SUM(R9:T9) -> 984000 | W10: =SUM(U9:W9) -> 1187500 | Z10: =SUM(X9:Z9) -> 1383000 | AC10: =SUM(AA9:AC9) -> 1666700 | AF10: =SUM(AD9:AF9) -> 1986600 | AI10: =SUM(AG9:AI9) -> 2377500 | AL10: =SUM(AJ9:AL9) -> 2870700
A12: MRR table | C12: 0 | D12: 0 | E12: 0 | F12: 0 | G12: 0 | H12: 0 | I12: 0 | J12: 0 | K12: 0 | L12: 0 | M12: 0 | N12: 0
C13: 0 | D13: =$D3/12 -> 2500 | E13: =$D3/12 -> 2500 | F13: =$D3/12 -> 2500 | G13: =$D3/12 -> 2500 | H13: =$D3/12 -> 2500 | I13: =$D3/12 -> 2500 | J13: =$D3/12 -> 2500 | K13: =$D3/12 -> 2500 | ... O13: =$D3/12 -> 2500
A14: Avrg. Unit Price | B14: 30000 | C14: Annual | E14: =$E3/12 -> 5000 | F14: =$E3/12 -> 5000 | G14: =$E3/12 -> 5000 | H14: =$E3/12 -> 5000 | I14: =$E3/12 -> 5000 | J14: =$E3/12 -> 5000 | K14: =$E3/12 -> 5000 | L14: =$E3/12 -> 5000 | ... P14: =$E3/12 -> 5000
A15: Professional Services revenue | F15: =$F3/12 -> 5000 | G15: =$F3/12 -> 5000 | H15: =$F3/12 -> 5000 | I15: =$F3/12 -> 5000 | J15: =$F3/12 -> 5000 | K15: =$F3/12 -> 5000 | L15: =$F3/12 -> 5000 | M15: =$F3/12 -> 5000 | ... Q15: =$F3/12 -> 5000
A16: Ratio to Bookings | B16: 0.3 | G16: =$G3/12 -> 10000 | H16: =$G3/12 -> 10000 | I16: =$G3/12 -> 10000 | J16: =$G3/12 -> 10000 | K16: =$G3/12 -> 10000 | L16: =$G3/12 -> 10000 | M16: =$G3/12 -> 10000 | N16: =$G3/12 -> 10000 | ... R16: =$G3/12 -> 10000
H17: =$H3/12 -> 10000 | I17: =$H3/12 -> 10000 | J17: =$H3/12 -> 10000 | K17: =$H3/12 -> 10000 | L17: =$H3/12 -> 10000 | M17: =$H3/12 -> 10000 | N17: =$H3/12 -> 10000 | O17: =$H3/12 -> 10000 | ... S17: =$H3/12 -> 10000
A18: Only cells in light blue should be edited | I18: =$I3/12 -> 12500 | J18: =$I3/12 -> 12500 | K18: =$I3/12 -> 12500 | L18: =$I3/12 -> 12500 | M18: =$I3/12 -> 12500 | N18: =$I3/12 -> 12500 | O18: =$I3/12 -> 12500 | P18: =$I3/12 -> 12500 | ... T18: =$I3/12 -> 12500
J19: =$J$3/12 -> 12500 | K19: =$J$3/12 -> 12500 | L19: =$J$3/12 -> 12500 | M19: =$J$3/12 -> 12500 | N19: =$J$3/12 -> 12500 | O19: =$J$3/12 -> 12500 | P19: =$J$3/12 -> 12500 | Q19: =$J$3/12 -> 12500 | ... U19: =$J$3/12 -> 12500
A20: March 1, 2025 revision -- Arik Paran -- SCORE Silicon Valley | K20: =$K$3/12 -> 15000 | L20: =$K$3/12 -> 15000 | M20: =$K$3/12 -> 15000 | N20: =$K$3/12 -> 15000 | O20: =$K$3/12 -> 15000 | P20: =$K$3/12 -> 15000 | Q20: =$K$3/12 -> 15000 | R20: =$K$3/12 -> 15000 | ... V20: =$K$3/12 -> 15000
L21: =$L$3/12 -> 15000 | M21: =$L$3/12 -> 15000 | N21: =$L$3/12 -> 15000 | O21: =$L$3/12 -> 15000 | P21: =$L$3/12 -> 15000 | Q21: =$L$3/12 -> 15000 | R21: =$L$3/12 -> 15000 | S21: =$L$3/12 -> 15000 | ... W21: =$L$3/12 -> 15000
M22: =$M$3/12 -> 20000 | N22: =$M$3/12 -> 20000 | O22: =$M$3/12 -> 20000 | P22: =$M$3/12 -> 20000 | Q22: =$M$3/12 -> 20000 | R22: =$M$3/12 -> 20000 | S22: =$M$3/12 -> 20000 | T22: =$M$3/12 -> 20000 | ... X22: =$M$3/12 -> 20000
N23: =$N$3/12 -> 20000 | O23: =$N$3/12 -> 20000 | P23: =$N$3/12 -> 20000 | Q23: =$N$3/12 -> 20000 | R23: =$N$3/12 -> 20000 | S23: =$N$3/12 -> 20000 | T23: =$N$3/12 -> 20000 | U23: =$N$3/12 -> 20000 | ... Y23: =$N$3/12 -> 20000
O24: =$O$3/12 -> 20000 | P24: =$O$3/12 -> 20000 | Q24: =$O$3/12 -> 20000 | R24: =$O$3/12 -> 20000 | S24: =$O$3/12 -> 20000 | T24: =$O$3/12 -> 20000 | U24: =$O$3/12 -> 20000 | V24: =$O$3/12 -> 20000 | ... Z24: =$O$3/12 -> 20000
P25: =$P$3/12 -> 20000 | Q25: =$P$3/12 -> 20000 | R25: =$P$3/12 -> 20000 | S25: =$P$3/12 -> 20000 | T25: =$P$3/12 -> 20000 | U25: =$P$3/12 -> 20000 | V25: =$P$3/12 -> 20000 | W25: =$P$3/12 -> 20000 | ... AA25: =$P$3/12 -> 20000
Q26: =$Q$3/12 -> 25000 | R26: =$Q$3/12 -> 25000 | S26: =$Q$3/12 -> 25000 | T26: =$Q$3/12 -> 25000 | U26: =$Q$3/12 -> 25000 | V26: =$Q$3/12 -> 25000 | W26: =$Q$3/12 -> 25000 | X26: =$Q$3/12 -> 25000 | ... AB26: =$Q$3/12 -> 25000
R27: =$R$3/12 -> 25000 | S27: =$R$3/12 -> 25000 | T27: =$R$3/12 -> 25000 | U27: =$R$3/12 -> 25000 | V27: =$R$3/12 -> 25000 | W27: =$R$3/12 -> 25000 | X27: =$R$3/12 -> 25000 | Y27: =$R$3/12 -> 25000 | ... AC27: =$R$3/12 -> 25000
S28: =$S$3/12 -> 25000 | T28: =$S$3/12 -> 25000 | U28: =$S$3/12 -> 25000 | V28: =$S$3/12 -> 25000 | W28: =$S$3/12 -> 25000 | X28: =$S$3/12 -> 25000 | Y28: =$S$3/12 -> 25000 | Z28: =$S$3/12 -> 25000 | ... AD28: =$S$3/12 -> 25000
T29: =$T$3/12 -> 25000 | U29: =$T$3/12 -> 25000 | V29: =$T$3/12 -> 25000 | W29: =$T$3/12 -> 25000 | X29: =$T$3/12 -> 25000 | Y29: =$T$3/12 -> 25000 | Z29: =$T$3/12 -> 25000 | AA29: =$T$3/12 -> 25000 | ... AE29: =$T$3/12 -> 25000
U30: =$U$3/12 -> 25000 | V30: =$U$3/12 -> 25000 | W30: =$U$3/12 -> 25000 | X30: =$U$3/12 -> 25000 | Y30: =$U$3/12 -> 25000 | Z30: =$U$3/12 -> 25000 | AA30: =$U$3/12 -> 25000 | AB30: =$U$3/12 -> 25000 | ... AF30: =$U$3/12 -> 25000
V31: =$V$3/12 -> 25000 | W31: =$V$3/12 -> 25000 | X31: =$V$3/12 -> 25000 | Y31: =$V$3/12 -> 25000 | Z31: =$V$3/12 -> 25000 | AA31: =$V$3/12 -> 25000 | AB31: =$V$3/12 -> 25000 | AC31: =$V$3/12 -> 25000 | ... AG31: =$V$3/12 -> 25000
W32: =$W$3/12 -> 25000 | X32: =$W$3/12 -> 25000 | Y32: =$W$3/12 -> 25000 | Z32: =$W$3/12 -> 25000 | AA32: =$W$3/12 -> 25000 | AB32: =$W$3/12 -> 25000 | AC32: =$W$3/12 -> 25000 | AD32: =$W$3/12 -> 25000 | ... AH32: =$W$3/12 -> 25000
X33: =$X$3/12 -> 25000 | Y33: =$X$3/12 -> 25000 | Z33: =$X$3/12 -> 25000 | AA33: =$X$3/12 -> 25000 | AB33: =$X$3/12 -> 25000 | AC33: =$X$3/12 -> 25000 | AD33: =$X$3/12 -> 25000 | AE33: =$X$3/12 -> 25000 | ... AI33: =$X$3/12 -> 25000
Y34: =$Y$3/12 -> 25000 | Z34: =$Y$3/12 -> 25000 | AA34: =$Y$3/12 -> 25000 | AB34: =$Y$3/12 -> 25000 | AC34: =$Y$3/12 -> 25000 | AD34: =$Y$3/12 -> 25000 | AE34: =$Y$3/12 -> 25000 | AF34: =$Y$3/12 -> 25000 | ... AJ34: =$Y$3/12 -> 25000
Z35: =$Z$3/12 -> 25000 | AA35: =$Z$3/12 -> 25000 | AB35: =$Z$3/12 -> 25000 | AC35: =$Z$3/12 -> 25000 | AD35: =$Z$3/12 -> 25000 | AE35: =$Z$3/12 -> 25000 | AF35: =$Z$3/12 -> 25000 | AG35: =$Z$3/12 -> 25000 | ... AK35: =$Z$3/12 -> 25000
AA36: =$AA$3/12 -> 30000 | AB36: =$AA$3/12 -> 30000 | AC36: =$AA$3/12 -> 30000 | AD36: =$AA$3/12 -> 30000 | AE36: =$AA$3/12 -> 30000 | AF36: =$AA$3/12 -> 30000 | AG36: =$AA$3/12 -> 30000 | AH36: =$AA$3/12 -> 30000 | ... AL36: =$AA$3/12 -> 30000
AB37: =$AB$3/12 -> 30000 | AC37: =$AB$3/12 -> 30000 | AD37: =$AB$3/12 -> 30000 | AE37: =$AB$3/12 -> 30000 | AF37: =$AB$3/12 -> 30000 | AG37: =$AB$3/12 -> 30000 | AH37: =$AB$3/12 -> 30000 | AI37: =$AB$3/12 -> 30000 | ... AL37: =$AB$3/12 -> 30000
AC38: =$AC$3/12 -> 30000 | AD38: =$AC$3/12 -> 30000 | AE38: =$AC$3/12 -> 30000 | AF38: =$AC$3/12 -> 30000 | AG38: =$AC$3/12 -> 30000 | AH38: =$AC$3/12 -> 30000 | AI38: =$AC$3/12 -> 30000 | AJ38: =$AC$3/12 -> 30000 | ... AL38: =$AC$3/12 -> 30000
AD39: =$AD$3/12 -> 30000 | AE39: =$AD$3/12 -> 30000 | AF39: =$AD$3/12 -> 30000 | AG39: =$AD$3/12 -> 30000 | AH39: =$AD$3/12 -> 30000 | AI39: =$AD$3/12 -> 30000 | AJ39: =$AD$3/12 -> 30000 | AK39: =$AD$3/12 -> 30000 | AL39: =$AD$3/12 -> 30000
AE40: =$AE$3/12 -> 37500 | AF40: =$AE$3/12 -> 37500 | AG40: =$AE$3/12 -> 37500 | AH40: =$AE$3/12 -> 37500 | AI40: =$AE$3/12 -> 37500 | AJ40: =$AE$3/12 -> 37500 | AK40: =$AE$3/12 -> 37500 | AL40: =$AE$3/12 -> 37500
AF41: =$AF$3/12 -> 37500 | AG41: =$AF$3/12 -> 37500 | AH41: =$AF$3/12 -> 37500 | AI41: =$AF$3/12 -> 37500 | AJ41: =$AF$3/12 -> 37500 | AK41: =$AF$3/12 -> 37500 | AL41: =$AF$3/12 -> 37500
AG42: =$AG$3/12 -> 37500 | AH42: =$AG$3/12 -> 37500 | AI42: =$AG$3/12 -> 37500 | AJ42: =$AG$3/12 -> 37500 | AK42: =$AG$3/12 -> 37500 | AL42: =$AG$3/12 -> 37500
AH43: =$AH$3/12 -> 37500 | AI43: =$AG$3/12 -> 37500 | AJ43: =$AG$3/12 -> 37500 | AK43: =$AG$3/12 -> 37500 | AL43: =$AG$3/12 -> 37500
...

Sheet P&L
A1: Month | B1: 1 | C1: =B1+1 -> 2 | D1: =C1+1 -> 3 | E1: =D1+1 -> 4 | F1: =E1+1 -> 5 | G1: =F1+1 -> 6 | H1: =G1+1 -> 7 | I1: =H1+1 -> 8 | J1: =I1+1 -> 9 | ... AK1: =AJ1+1 -> 36
A2: New Customers | B2: ='Revenue model'!C2 -> 0 | C2: ='Revenue model'!D2 -> 1 | D2: ='Revenue model'!E2 -> 2 | E2: ='Revenue model'!F2 -> 2 | F2: ='Revenue model'!G2 -> 4 | G2: ='Revenue model'!H2 -> 4 | H2: ='Revenue model'!I2 -> 5 | I2: ='Revenue model'!J2 -> 5 | ... AK2: ='Revenue model'!AL2 -> 20
A3: Total Customers | B3: =B2 -> 0 | C3: =C2+B3 -> 1 | D3: =D2+C3 -> 3 | E3: =E2+D3 -> 5 | F3: =F2+E3 -> 9 | G3: =G2+F3 -> 13 | H3: =H2+G3 -> 18 | I3: =I2+H3 -> 23 | J3: =J2+I3 -> 29 | ... AK3: =AK2+AJ3 -> 355
A4: New Bookings | B4: ='Revenue model'!C3 -> 0 | C4: ='Revenue model'!D3 -> 30000 | D4: ='Revenue model'!E3 -> 60000 | E4: ='Revenue model'!F3 -> 60000 | F4: ='Revenue model'!G3 -> 120000 | G4: ='Revenue model'!H3 -> 120000 | H4: ='Revenue model'!I3 -> 150000 | I4: ='Revenue model'!J3 -> 150000 | ... AK4: ='Revenue model'!AL3 -> 600000
A5: License Revenue | B5: ='Revenue model'!C9-'Revenue model'!C8 -> 0 | C5: ='Revenue model'!D9-'Revenue model'!D8 -> 2500 | D5: ='Revenue model'!E9-'Revenue model'!E8 -> 7500 | E5: ='Revenue model'!F9-'Revenue model'!F8 -> 12500 | F5: ='Revenue model'!G9-'Revenue model'!G8 -> 22500 | G5: ='Revenue model'!H9-'Revenue model'!H8 -> 32500 | H5: ='Revenue model'!I9-'Revenue model'!I8 -> 45000 | I5: ='Revenue model'!J9-'Revenue model'!J8 -> 57500 | ... AK5: ='Revenue model'!AL9-'Revenue model'!AL8 -> 822800
A6: PS Revenue | B6: ='Revenue model'!C8 -> 0 | C6: ='Revenue model'!D8 -> 9000 | D6: ='Revenue model'!E8 -> 18000 | E6: ='Revenue model'!F8 -> 18000 | F6: ='Revenue model'!G8 -> 36000 | G6: ='Revenue model'!H8 -> 36000 | H6: ='Revenue model'!I8 -> 45000 | I6: ='Revenue model'!J8 -> 45000 | ... AK6: ='Revenue model'!AL8 -> 180000
A7: Marking Expenses | B7: =$B35*C4 -> 4500 | C7: =$B35*D4 -> 9000 | D7: =$B35*E4 -> 9000 | E7: =$B35*F4 -> 18000 | F7: =$B35*G4 -> 18000 | G7: =$B35*H4 -> 22500 | H7: =$B35*I4 -> 22500 | I7: =$B35*J4 -> 27000 | ... AJ7: =$B35*AK4 -> 90000 | AK7: =$B35*AK4 -> 90000
A8: Sales Commission | B8: =$B33*B4 -> 0 | C8: =$B33*C4 -> 4500 | D8: =$B33*D4 -> 9000 | E8: =$B33*E4 -> 9000 | F8: =$B33*F4 -> 18000 | G8: =$B33*G4 -> 18000 | H8: =$B33*H4 -> 22500 | I8: =$B33*I4 -> 22500 | ... AK8: =$B33*AK4 -> 90000
A10: Sales people | B10: =D4*$B43/$B32 -> 0.45 | C10: =E4*$B43/$B32 -> 0.45 | D10: =F4*$B43/$B32 -> 0.9 | E10: =G4*$B43/$B32 -> 0.9 | F10: =H4*$B43/$B32 -> 1.125 | G10: =I4*$B43/$B32 -> 1.125 | H10: =J4*$B43/$B32 -> 1.35 | I10: =K4*$B43/$B32 -> 1.35 | ... AI10: =AK4*$B43/$B32 -> 4.5 | AJ10: =AI10+0.5 -> 5 | AK10: =AJ10+0.5 -> 5.5
A11: Sales OPS | B11: =B10*$B34 -> 0.045 | C11: =C10*$B34 -> 0.045 | D11: =D10*$B34 -> 0.09 | E11: =E10*$B34 -> 0.09 | F11: =F10*$B34 -> 0.1125 | G11: =G10*$B34 -> 0.1125 | H11: =H10*$B34 -> 0.135 | I11: =I10*$B34 -> 0.135 | ... AK11: =AK10*$B34 -> 0.55
A12: Customer Success staff | B12: =$B29*$B41*B5/$B26 -> 0 | C12: =$B29*$B41*C5/$B26 -> 0.015 | D12: =$B29*$B41*D5/$B26 -> 0.045 | E12: =$B29*$B41*E5/$B26 -> 0.075 | F12: =$B29*$B41*F5/$B26 -> 0.135 | G12: =$B29*$B41*G5/$B26 -> 0.195 | H12: =$B29*$B41*H5/$B26 -> 0.27 | I12: =$B29*$B41*I5/$B26 -> 0.345 | ... AK12: =$B29*$B41*AK5/$B26 -> 4.9368
A13: Support Staff | B13: =$B30*$B40*B5/$B26 -> 0 | C13: =$B30*$B40*C5/$B26 -> 0.0025 | D13: =$B30*$B40*D5/$B26 -> 0.0075 | E13: =$B30*$B40*E5/$B26 -> 0.0125 | F13: =$B30*$B40*F5/$B26 -> 0.0225 | G13: =$B30*$B40*G5/$B26 -> 0.0325 | H13: =$B30*$B40*H5/$B26 -> 0.045 | I13: =$B30*$B40*I5/$B26 -> 0.0575 | ... AK13: =$B30*$B40*AK5/$B26 -> 0.8228
A14: PS staff
A16: Headcount
A17: Sales | B17: =1+ROUNDUP(B10+B11,0) -> 2 | C17: =1+ROUNDUP(C10+C11,0) -> 2 | D17: =1+ROUNDUP(D10+D11,0) -> 2 | E17: =1+ROUNDUP(E10+E11,0) -> 2 | F17: =1+ROUNDUP(F10+F11,0) -> 3 | G17: =1+ROUNDUP(G10+G11,0) -> 3 | H17: =1+ROUNDUP(H10+H11,0) -> 3 | I17: =1+ROUNDUP(I10+I11,0) -> 3 | ... AK17: =1+ROUNDUP(AK10+AK11,0) -> 8
A18: Cust. Succ. + Support | B18: =1+ROUNDUP(B12+B13,0) -> 1 | C18: =1+ROUNDUP(C12+C13,0) -> 2 | D18: =1+ROUNDUP(D12+D13,0) -> 2 | E18: =1+ROUNDUP(E12+E13,0) -> 2 | F18: =1+ROUNDUP(F12+F13,0) -> 2 | G18: =1+ROUNDUP(G12+G13,0) -> 2 | H18: =1+ROUNDUP(H12+H13,0) -> 2 | I18: =1+ROUNDUP(I12+I13,0) -> 2 | ... AK18: =1+ROUNDUP(AK12+AK13,0) -> 7
A19: Professional Services | B19: =1+ROUNDUP(B6*$B42/$B31,0) -> 1 | C19: =1+ROUNDUP(C6*$B42/$B31,0) -> 2 | D19: =1+ROUNDUP(D6*$B42/$B31,0) -> 2 | E19: =1+ROUNDUP(E6*$B42/$B31,0) -> 2 | F19: =1+ROUNDUP(F6*$B42/$B31,0) -> 3 | G19: =1+ROUNDUP(G6*$B42/$B31,0) -> 3 | H19: =1+ROUNDUP(H6*$B42/$B31,0) -> 3 | I19: =1+ROUNDUP(I6*$B42/$B31,0) -> 3 | ... AK19: =1+ROUNDUP(AK6*$B42/$B31,0) -> 9
A20: Marketing | B20: 2 | C20: 2 | D20: 2 | E20: 2 | F20: 2 | G20: 2 | H20: 2 | I20: 2 | J20: 2 | K20: 2 | L20: 2 | M20: 2 | N20: 3 | O20: 3 | P20: 3 | Q20: 3 | R20: 3 | S20: 3 | T20: 3 | U20: 3 | V20: 3 | W20: 3 | X20: 3 | Y20: 3 | Z20: 3 | AA20: 3 | AB20: 3 | AC20: 3 | AD20: 3 | AE20: 3 | AF20: 3 | AG20: 3 | AH20: 3 | AI20: 3 | AJ20: 3 | AK20: 3
A21: Engineering | B21: 3 | C21: 3 | D21: 3 | E21: 3 | F21: 3 | G21: 3 | H21: 3 | I21: 3 | J21: 3 | K21: 3 | L21: 3 | M21: 3 | N21: 5 | O21: 5 | P21: 5 | Q21: 5 | R21: 5 | S21: 5 | T21: 5 | U21: 5 | V21: 5 | W21: 5 | X21: 5 | Y21: 5 | Z21: 5 | AA21: 5 | AB21: 5 | AC21: 5 | AD21: 5 | AE21: 5 | AF21: 5 | AG21: 5 | AH21: 5 | AI21: 5 | AJ21: 5 | AK21: 5
A22: G&A | B22: 2 | C22: 2 | D22: 2 | E22: 2 | F22: 2 | G22: 2 | H22: 3 | I22: 3 | J22: 3 | K22: 3 | L22: 3 | M22: 3 | N22: 3 | O22: 3 | P22: 3 | Q22: 3 | R22: 3 | S22: 3 | T22: 4 | U22: 4 | V22: 4 | W22: 4 | X22: 4 | Y22: 4 | Z22: 4 | AA22: 4 | AB22: 4 | AC22: 4 | AD22: 4 | AE22: 4 | AF22: 5 | AG22: 5 | AH22: 5 | AI22: 5 | AJ22: 5 | AK22: 5
A23: Total HC | B23: =SUM(B17:B22) -> 11 | C23: =SUM(C17:C22) -> 13 | D23: =SUM(D17:D22) -> 13 | E23: =SUM(E17:E22) -> 13 | F23: =SUM(F17:F22) -> 15 | G23: =SUM(G17:G22) -> 15 | H23: =SUM(H17:H22) -> 16 | I23: =SUM(I17:I22) -> 16 | ... AK23: =SUM(AK17:AK22) -> 37
A25: Avrg Price | B25: ='Revenue model'!B14 -> 30000 | C25: from Revenue Model
A26: Avrg HC cost | B26: 10000 | C26: Monthly | G26: You must edit the marketing, engineering, and G&A headcount numbers above
A27: G&A overhead | B27: 0.25 | C27: of G&A headcount
A28: AI Agents cost (avrg) | B28: 10000 | C28: Per headcount | E28: Adjust!
A29: Customer Success Ratio | B29: 0.2 | C29: of Revenue (cost of CS) | G29: Only cells in light blue should be edited
A30: Support Ratio | B30: 0.05 | C30: of Revenue (cost of support)
A31: Pro. Serv. capacity | B31: 18000 | C31: Monthly revenue capacity per person
A32: Sales qouta monthly | B32: 100000 | C32: of Bookings | D32: 6 months out | G32: March 1, 2025 revision -- Arik Paran -- SCORE Silicon Valley | L32: Updated with new AI effects
A33: Sales commission Rate | B33: 0.15 | C33: of Bookings
A34: Sales/OPS ratio | B34: 0.1 | C34: Sales OPS HC ratio to Sales people HC
A35: Markteting Cost Ratio | B35: 0.15 | C35: of Bookings | D35: 3 months out
A37: Engineering AI factor | B37: 0.5 | C37: Remaining effort with AI leverage (manual) | G37: Review your headcount and adjust accoring to technology use to Leverage AI agents
A38: G&A AI factor | B38: 0.75 | C38: Remaining effort with AI leverage (manual) | G38: Review your headcount and adjust accoring to technology use to Leverage AI agents
A39: Marketing AI factor | B39: 0.5 | C39: Remaining effort with AI leverage (manual) | G39: Review your headcount and adjust accoring to technology use to Leverage AI agents
A40: Customer Support AI factor | B40: 0.2 | C40: Remaining effort with AI leverage (auto) | G40: Factor is already within the functions in the tables above
A41: Customer Success AI factor | B41: 0.3 | C41: Remaining effort with AI leverage (auto) | G41: Factor is already within the functions in the tables above
A42: Prof. Servicves AI factor | B42: 0.75 | C42: Remaining effort with AI leverage (auto) | G42: Factor is already within the functions in the tables above
A43: Sales AI factor | B43: 0.75 | C43: Remaining effort with AI leverage (auto) | G43: Factor is already within the functions in the tables above
A46: P&L
...
